<?xml version="1.0" encoding="utf-8"?>
<!-- This URDF was automatically created by SolidWorks to URDF Exporter! Originally created by Stephen Brawner (brawner@gmail.com) 
     Commit Version: 1.5.1-0-g916b5db  Build Version: 1.5.7152.31018
     For more information, please see http://wiki.ros.org/sw_urdf_exporter -->
<robot
  name="GSC_6dof_initial_robot">
  <link
    name="base_link">
    <inertial>
      <origin
        xyz="-2.61177968803165E-10 1.10836536810847E-09 0.00842758262058745"
        rpy="0 0 0" />
      <mass
        value="0.582285408462786" />
      <inertia
        ixx="0.00114248548303506"
        ixy="1.77102209808692E-11"
        ixz="-1.16651932498346E-11"
        iyy="0.0011424854745287"
        iyz="-2.03737865797445E-11"
        izz="0.00224223516153538" />
    </inertial>
    <visual>
      <origin
        xyz="0 0 0"
        rpy="0 0 0" />
      <geometry>
        <mesh
          filename="package://GSC_6dof_initial_robot/meshes/base_link.STL" />
      </geometry>
      <material
        name="">
        <color
          rgba="0.898039215686275 0.917647058823529 0.929411764705882 1" />
      </material>
    </visual>
    <collision>
      <origin
        xyz="0 0 0"
        rpy="0 0 0" />
      <geometry>
        <mesh
          filename="package://GSC_6dof_initial_robot/meshes/base_link.STL" />
      </geometry>
    </collision>
  </link>
  <link
    name="link_1">
    <inertial>
      <origin
        xyz="1.3384E-06 -0.0049524 -0.024551"
        rpy="0 0 0" />
      <mass
        value="2.9258" />
      <inertia
        ixx="0.0092637"
        ixy="1.871E-07"
        ixz="-2.8798E-08"
        iyy="0.0089789"
        iyz="0.00035176"
        izz="0.007138" />
    </inertial>
    <visual>
      <origin
        xyz="0 0 0"
        rpy="0 0 0" />
      <geometry>
        <mesh
          filename="package://GSC_6dof_initial_robot/meshes/link_1.STL" />
      </geometry>
      <material
        name="">
        <color
          rgba="0.89804 0.91765 0.92941 1" />
      </material>
    </visual>
    <collision>
      <origin
        xyz="0 0 0"
        rpy="0 0 0" />
      <geometry>
        <mesh
          filename="package://GSC_6dof_initial_robot/meshes/link_1.STL" />
      </geometry>
    </collision>
  </link>
  <joint
    name="joint_1"
    type="revolute">
    <origin
      xyz="0 0 0.103"
      rpy="0 0 0" />
    <parent
      link="base_link" />
    <child
      link="link_1" />
    <axis
      xyz="0 0 1" />
    <limit
      lower="-3.14"
      upper="3.14"
      effort="150"
      velocity="3" />
    <safety_controller
      k_velocity="0" />
  </joint>
  <link
    name="link_2">
    <inertial>
      <origin
        xyz="0.213 -4.2737E-13 0.13086"
        rpy="0 0 0" />
      <mass
        value="7.134" />
      <inertia
        ixx="0.021752"
        ixy="1.2551E-06"
        ixz="-5.6607E-14"
        iyy="0.2839"
        iyz="-2.9872E-14"
        izz="0.27902" />
    </inertial>
    <visual>
      <origin
        xyz="0 0 0"
        rpy="0 0 0" />
      <geometry>
        <mesh
          filename="package://GSC_6dof_initial_robot/meshes/link_2.STL" />
      </geometry>
      <material
        name="">
        <color
          rgba="0.89804 0.91765 0.92941 1" />
      </material>
    </visual>
    <collision>
      <origin
        xyz="0 0 0"
        rpy="0 0 0" />
      <geometry>
        <mesh
          filename="package://GSC_6dof_initial_robot/meshes/link_2.STL" />
      </geometry>
    </collision>
  </link>
  <joint
    name="joint_2"
    type="revolute">
    <origin
      xyz="0 0 0"
      rpy="1.5708 -1.5708 0" />
    <parent
      link="link_1" />
    <child
      link="link_2" />
    <axis
      xyz="0 0 1" />
    <limit
      lower="-3.14"
      upper="3.14"
      effort="150"
      velocity="3" />
    <safety_controller
      k_velocity="0" />
  </joint>
  <link
    name="link_3">
    <inertial>
      <origin
        xyz="0.25363 2.6591E-07 0.013039"
        rpy="0 0 0" />
      <mass
        value="3.5587" />
      <inertia
        ixx="0.0091511"
        ixy="-1.8597E-07"
        ixz="-0.0068641"
        iyy="0.11315"
        iyz="-1.1116E-07"
        izz="0.11107" />
    </inertial>
    <visual>
      <origin
        xyz="0 0 0"
        rpy="0 0 0" />
      <geometry>
        <mesh
          filename="package://GSC_6dof_initial_robot/meshes/link_3.STL" />
      </geometry>
      <material
        name="">
        <color
          rgba="0.66667 0.66667 0.66667 1" />
      </material>
    </visual>
    <collision>
      <origin
        xyz="0 0 0"
        rpy="0 0 0" />
      <geometry>
        <mesh
          filename="package://GSC_6dof_initial_robot/meshes/link_3.STL" />
      </geometry>
    </collision>
  </link>
  <joint
    name="joint_3"
    type="revolute">
    <origin
      xyz="0.426 0 0"
      rpy="0 0 0" />
    <parent
      link="link_2" />
    <child
      link="link_3" />
    <axis
      xyz="0 0 1" />
    <limit
      lower="-3.14"
      upper="3.14"
      effort="150"
      velocity="3" />
    <safety_controller
      k_velocity="0" />
  </joint>
  <link
    name="link_4">
    <inertial>
      <origin
        xyz="-5.4535E-07 -0.021096 -0.0047608"
        rpy="0 0 0" />
      <mass
        value="1.6688" />
      <inertia
        ixx="0.0044122"
        ixy="-8.8727E-08"
        ixz="6.9423E-08"
        iyy="0.0030144"
        iyz="0.00016404"
        izz="0.0042914" />
    </inertial>
    <visual>
      <origin
        xyz="0 0 0"
        rpy="0 0 0" />
      <geometry>
        <mesh
          filename="package://GSC_6dof_initial_robot/meshes/link_4.STL" />
      </geometry>
      <material
        name="">
        <color
          rgba="0.89804 0.91765 0.92941 1" />
      </material>
    </visual>
    <collision>
      <origin
        xyz="0 0 0"
        rpy="0 0 0" />
      <geometry>
        <mesh
          filename="package://GSC_6dof_initial_robot/meshes/link_4.STL" />
      </geometry>
    </collision>
  </link>
  <joint
    name="joint_4"
    type="revolute">
    <origin
      xyz="0.414 0 0.1385"
      rpy="0 0 1.5708" />
    <parent
      link="link_3" />
    <child
      link="link_4" />
    <axis
      xyz="0 0 1" />
    <limit
      lower="-3.14"
      upper="3.14"
      effort="50"
      velocity="3" />
    <safety_controller
      k_velocity="0" />
  </joint>
  <link
    name="link_5">
    <inertial>
      <origin
        xyz="6.0717E-07 0.015883 -0.0053082"
        rpy="0 0 0" />
      <mass
        value="1.4967" />
      <inertia
        ixx="0.0038292"
        ixy="-9.3394E-08"
        ixz="-6.9913E-08"
        iyy="0.0028772"
        iyz="-0.00012262"
        izz="0.0037126" />
    </inertial>
    <visual>
      <origin
        xyz="0 0 0"
        rpy="0 0 0" />
      <geometry>
        <mesh
          filename="package://GSC_6dof_initial_robot/meshes/link_5.STL" />
      </geometry>
      <material
        name="">
        <color
          rgba="0.89804 0.91765 0.92941 1" />
      </material>
    </visual>
    <collision>
      <origin
        xyz="0 0 0"
        rpy="0 0 0" />
      <geometry>
        <mesh
          filename="package://GSC_6dof_initial_robot/meshes/link_5.STL" />
      </geometry>
    </collision>
  </link>
  <joint
    name="joint_5"
    type="revolute">
    <origin
      xyz="0 -0.134 0"
      rpy="1.5708 0 0" />
    <parent
      link="link_4" />
    <child
      link="link_5" />
    <axis
      xyz="0 0 1" />
    <limit
      lower="-3.14"
      upper="3.14"
      effort="50"
      velocity="3" />
    <safety_controller
      k_velocity="0" />
  </joint>
  <link
    name="link_6">
    <inertial>
      <origin
        xyz="-1.4008E-08 -9.3958E-09 -0.0050077"
        rpy="0 0 0" />
      <mass
        value="0.14138" />
      <inertia
        ixx="6.5906E-05"
        ixy="-9.2283E-14"
        ixz="-4.4356E-13"
        iyy="6.5906E-05"
        iyz="-3.283E-13"
        izz="0.00012932" />
    </inertial>
    <visual>
      <origin
        xyz="0 0 0"
        rpy="0 0 0" />
      <geometry>
        <mesh
          filename="package://GSC_6dof_initial_robot/meshes/link_6.STL" />
      </geometry>
      <material
        name="">
        <color
          rgba="0.89804 0.91765 0.92941 1" />
      </material>
    </visual>
    <collision>
      <origin
        xyz="0 0 0"
        rpy="0 0 0" />
      <geometry>
        <mesh
          filename="package://GSC_6dof_initial_robot/meshes/link_6.STL" />
      </geometry>
    </collision>
  </link>
  <joint
    name="joiont_6"
    type="revolute">
    <origin
      xyz="0 0.081 0"
      rpy="-1.5708 0 0" />
    <parent
      link="link_5" />
    <child
      link="link_6" />
    <axis
      xyz="0 0 1" />
    <limit
      lower="-3.14"
      upper="3.14"
      effort="50"
      velocity="3" />
    <safety_controller
      k_velocity="0" />
  </joint>
</robot>