<?xml version="1.0" encoding="utf-8"?>
<!-- This URDF was automatically created by SolidWorks to URDF Exporter! Originally created by Stephen Brawner (brawner@gmail.com) 
     Commit Version: 1.5.1-0-g916b5db  Build Version: 1.5.7152.31018
     For more information, please see http://wiki.ros.org/sw_urdf_exporter -->
<robot
  name="GSC_with_load">
  <link
    name="base_link">
    <inertial>
      <origin
        xyz="-2.61177968836726E-10 1.10836536789464E-09 0.00842758262058745"
        rpy="0 0 0" />
      <mass
        value="0.582285408462786" />
      <inertia
        ixx="0.00114248548303506"
        ixy="1.77102209826141E-11"
        ixz="-1.16651932494418E-11"
        iyy="0.0011424854745287"
        iyz="-2.03737865800795E-11"
        izz="0.00224223516153538" />
    </inertial>
    <visual>
      <origin
        xyz="0 0 0"
        rpy="0 0 0" />
      <geometry>
        <mesh
          filename="package://GSC_with_load/meshes/base_link.STL" />
      </geometry>
      <material
        name="">
        <color
          rgba="0.898039215686275 0.917647058823529 0.929411764705882 1" />
      </material>
    </visual>
    <collision>
      <origin
        xyz="0 0 0"
        rpy="0 0 0" />
      <geometry>
        <mesh
          filename="package://GSC_with_load/meshes/base_link.STL" />
      </geometry>
    </collision>
  </link>
  <link
    name="Link_1">
    <inertial>
      <origin
        xyz="1.3384E-06 -0.0049524 -0.024551"
        rpy="0 0 0" />
      <mass
        value="2.9258" />
      <inertia
        ixx="0.0092637"
        ixy="1.871E-07"
        ixz="-2.8798E-08"
        iyy="0.0089789"
        iyz="0.00035176"
        izz="0.007138" />
    </inertial>
    <visual>
      <origin
        xyz="0 0 0"
        rpy="0 0 0" />
      <geometry>
        <mesh
          filename="package://GSC_with_load/meshes/Link_1.STL" />
      </geometry>
      <material
        name="">
        <color
          rgba="0.89804 0.91765 0.92941 1" />
      </material>
    </visual>
    <collision>
      <origin
        xyz="0 0 0"
        rpy="0 0 0" />
      <geometry>
        <mesh
          filename="package://GSC_with_load/meshes/Link_1.STL" />
      </geometry>
    </collision>
  </link>
  <joint
    name="joint_1"
    type="revolute">
    <origin
      xyz="0 0 0.103"
      rpy="0 0 0" />
    <parent
      link="base_link" />
    <child
      link="Link_1" />
    <axis
      xyz="0 0 1" />
    <limit
      lower="-3.14"
      upper="3.14"
      effort="150"
      velocity="3" />
  </joint>
  <link
    name="Link_2">
    <inertial>
      <origin
        xyz="0.213 -4.2745E-13 0.13086"
        rpy="0 0 0" />
      <mass
        value="7.134" />
      <inertia
        ixx="0.021752"
        ixy="1.2551E-06"
        ixz="-5.6646E-14"
        iyy="0.2839"
        iyz="-2.9872E-14"
        izz="0.27902" />
    </inertial>
    <visual>
      <origin
        xyz="0 0 0"
        rpy="0 0 0" />
      <geometry>
        <mesh
          filename="package://GSC_with_load/meshes/Link_2.STL" />
      </geometry>
      <material
        name="">
        <color
          rgba="0.89804 0.91765 0.92941 1" />
      </material>
    </visual>
    <collision>
      <origin
        xyz="0 0 0"
        rpy="0 0 0" />
      <geometry>
        <mesh
          filename="package://GSC_with_load/meshes/Link_2.STL" />
      </geometry>
    </collision>
  </link>
  <joint
    name="joint_2"
    type="revolute">
    <origin
      xyz="0 0 0"
      rpy="1.5708 -1.5708 0" />
    <parent
      link="Link_1" />
    <child
      link="Link_2" />
    <axis
      xyz="0 0 1" />
    <limit
      lower="-3.14"
      upper="3.14"
      effort="150"
      velocity="3" />
  </joint>
  <link
    name="Link_3">
    <inertial>
      <origin
        xyz="0.253631832285622 2.65912527732819E-07 0.0130387864746914"
        rpy="0 0 0" />
      <mass
        value="3.55869113103108" />
      <inertia
        ixx="0.00915107720503709"
        ixy="-1.85972510797387E-07"
        ixz="-0.00686410273625125"
        iyy="0.113153687081063"
        iyz="-1.11158515773289E-07"
        izz="0.111073666851628" />
    </inertial>
    <visual>
      <origin
        xyz="0 0 0"
        rpy="0 0 0" />
      <geometry>
        <mesh
          filename="package://GSC_with_load/meshes/Link_3.STL" />
      </geometry>
      <material
        name="">
        <color
          rgba="0.666666666666667 0.666666666666667 0.666666666666667 1" />
      </material>
    </visual>
    <collision>
      <origin
        xyz="0 0 0"
        rpy="0 0 0" />
      <geometry>
        <mesh
          filename="package://GSC_with_load/meshes/Link_3.STL" />
      </geometry>
    </collision>
  </link>
  <joint
    name="joint3"
    type="revolute">
    <origin
      xyz="0.426 0 0"
      rpy="0 0 0" />
    <parent
      link="Link_2" />
    <child
      link="Link_3" />
    <axis
      xyz="0 0 1" />
    <limit
      lower="-3.14"
      upper="3.14"
      effort="150"
      velocity="3" />
  </joint>
  <link
    name="Link_4">
    <inertial>
      <origin
        xyz="-5.45347197881896E-07 -0.0210960934472068 -0.00476083658315146"
        rpy="0 0 0" />
      <mass
        value="1.66877908297273" />
      <inertia
        ixx="0.00441224786972239"
        ixy="-8.87272168551393E-08"
        ixz="6.94225390335798E-08"
        iyy="0.00301441064867338"
        iyz="0.000164042393077159"
        izz="0.00429135267006557" />
    </inertial>
    <visual>
      <origin
        xyz="0 0 0"
        rpy="0 0 0" />
      <geometry>
        <mesh
          filename="package://GSC_with_load/meshes/Link_4.STL" />
      </geometry>
      <material
        name="">
        <color
          rgba="0.898039215686275 0.917647058823529 0.929411764705882 1" />
      </material>
    </visual>
    <collision>
      <origin
        xyz="0 0 0"
        rpy="0 0 0" />
      <geometry>
        <mesh
          filename="package://GSC_with_load/meshes/Link_4.STL" />
      </geometry>
    </collision>
  </link>
  <joint
    name="joint_4"
    type="revolute">
    <origin
      xyz="0.414 0 0.1385"
      rpy="0 0 1.5708" />
    <parent
      link="Link_3" />
    <child
      link="Link_4" />
    <axis
      xyz="0 0 1" />
    <limit
      lower="-3.14"
      upper="3.14"
      effort="50"
      velocity="3" />
  </joint>
  <link
    name="Link_5">
    <inertial>
      <origin
        xyz="6.07171407990862E-07 0.0158826301395855 -0.00530815289706887"
        rpy="0 0 0" />
      <mass
        value="1.49671394342634" />
      <inertia
        ixx="0.00382918583569587"
        ixy="-9.33943322363564E-08"
        ixz="-6.99133568399163E-08"
        iyy="0.00287716928810821"
        iyz="-0.000122622434451678"
        izz="0.0037126389518812" />
    </inertial>
    <visual>
      <origin
        xyz="0 0 0"
        rpy="0 0 0" />
      <geometry>
        <mesh
          filename="package://GSC_with_load/meshes/Link_5.STL" />
      </geometry>
      <material
        name="">
        <color
          rgba="0.898039215686275 0.917647058823529 0.929411764705882 1" />
      </material>
    </visual>
    <collision>
      <origin
        xyz="0 0 0"
        rpy="0 0 0" />
      <geometry>
        <mesh
          filename="package://GSC_with_load/meshes/Link_5.STL" />
      </geometry>
    </collision>
  </link>
  <joint
    name="joint_5"
    type="revolute">
    <origin
      xyz="0 -0.134 0"
      rpy="1.5708 0 0" />
    <parent
      link="Link_4" />
    <child
      link="Link_5" />
    <axis
      xyz="0 0 1" />
    <limit
      lower="-3.14"
      upper="3.14"
      effort="50"
      velocity="3" />
  </joint>
  <link
    name="Link_6">
    <inertial>
      <origin
        xyz="3.0278E-09 -4.0038E-09 0.046188"
        rpy="0 0 0" />
      <mass
        value="2.1898" />
      <inertia
        ixx="0.0036583"
        ixy="-4.343E-13"
        ixz="2.3993E-10"
        iyy="0.0041561"
        iyz="-3.3642E-10"
        izz="0.0019415" />
    </inertial>
    <visual>
      <origin
        xyz="0 0 0"
        rpy="0 0 0" />
      <geometry>
        <mesh
          filename="package://GSC_with_load/meshes/Link_6.STL" />
      </geometry>
      <material
        name="">
        <color
          rgba="0.75294 0.75294 0.75294 1" />
      </material>
    </visual>
    <collision>
      <origin
        xyz="0 0 0"
        rpy="0 0 0" />
      <geometry>
        <mesh
          filename="package://GSC_with_load/meshes/Link_6.STL" />
      </geometry>
    </collision>
  </link>
  <joint
    name="joint_6"
    type="revolute">
    <origin
      xyz="0 0.07 0"
      rpy="-1.5708 0 0" />
    <parent
      link="Link_5" />
    <child
      link="Link_6" />
    <axis
      xyz="0 0 1" />
    <limit
      lower="-3.14"
      upper="3.14"
      effort="50"
      velocity="3" />
  </joint>
</robot>